<?xml version="1.0" ?>
<!-- =================================================================================== -->
<!-- |    This document was autogenerated by xacro from rover.xacro                    | -->
<!-- |    EDITING THIS FILE BY HAND IS NOT RECOMMENDED                                 | -->
<!-- =================================================================================== -->
<robot name="rover">
  <gazebo>
    <plugin filename="libgazebo_ros_skid_steer_drive.so" name="skid_steer_drive_controller">
      <updateRate>10.0</updateRate>
      <robotNamespace>/</robotNamespace>
      <leftFrontJoint>left_wheel_hinge_front</leftFrontJoint>
      <rightFrontJoint>right_wheel_hinge_front</rightFrontJoint>
      <leftRearJoint>left_wheel_hinge_back</leftRearJoint>
      <rightRearJoint>right_wheel_hinge_back</rightRearJoint>
      <wheelSeparation>0.4</wheelSeparation>
      <wheelDiameter>0.2</wheelDiameter>
      <robotBaseFrame>robot_footprint</robotBaseFrame>
      <torque>10</torque>
      <topicName>cmd_vel</topicName>
      <odometryTopic>drive/odom</odometryTopic>
      <odometryFrame>odom</odometryFrame>
      <commandTopic>cmd_vel</commandTopic>
      <topic_name_twist>cmd_vel</topic_name_twist>
      <topic_name_odometry>drive/odom</topic_name_odometry>
      <topic_name_joint>joint</topic_name_joint>
      <broadcastTF>true</broadcastTF>
      <covariance_x>0.0001</covariance_x>
      <covariance_y>0.0001</covariance_y>
      <covariance_yaw>0.01</covariance_yaw>
    </plugin>
  </gazebo>
  <!-- camera -->
  <gazebo reference="camera">
    <sensor name="camera1" type="camera">
      <update_rate>30.0</update_rate>
      <camera name="head">
        <horizontal_fov>1.3962634</horizontal_fov>
        <image>
          <width>800</width>
          <height>800</height>
          <format>R8G8B8</format>
        </image>
        <clip>
          <near>0.02</near>
          <far>300</far>
        </clip>
      </camera>
      <plugin filename="libgazebo_ros_camera.so" name="camera_controller">
        <alwaysOn>true</alwaysOn>
        <updateRate>0.0</updateRate>
        <cameraName>camera</cameraName>
        <imageTopicName>image_raw</imageTopicName>
        <cameraInfoTopicName>camera_info</cameraInfoTopicName>
        <frameName>camera</frameName>
        <hackBaseline>0.07</hackBaseline>
        <distortionK1>0.0</distortionK1>
        <distortionK2>0.0</distortionK2>
        <distortionK3>0.0</distortionK3>
        <distortionT1>0.0</distortionT1>
        <distortionT2>0.0</distortionT2>
      </plugin>
    </sensor>
  </gazebo>
  <!-- lidar 2.3562-->
  <gazebo reference="lidar">
    <sensor name="lidar_sensor" type="lidar">
      <always_on>true</always_on>
      <update_rate>50</update_rate>
      <ray>
        <scan>
          <horizontal>
            <samples>360</samples>
            <min_angle>-2.3562</min_angle>
            <max_angle>2.3562</max_angle>
          </horizontal>
        </scan>
        <range>
          <min>0.3</min>
          <max>12</max>
        </range>
      </ray>
      <visualize>false</visualize>
      <topic>scan</topic>
      <plugin filename="libgazebo_ros_laser.so" name="gazebo_ros_lidar">
        <topicName>scan</topicName>
        <frameName>lidar</frameName>
        <fov>1.5708</fov>
        <min_range>0.02</min_range>
        <max_range>30.0</max_range>
        <horizontalSamples>720</horizontalSamples>
        <verticalSamples>1</verticalSamples>
        <pointsPerRay>1</pointsPerRay>
        <laserNoise>0.01</laserNoise>
      </plugin>
      <pose>0 0 0 0 0 0</pose>
    </sensor>
  </gazebo>
  <!-- imu -->
  <gazebo reference="imu">
    <sensor name="br_imu" type="imu">
        <always_on>true</always_on>
        <update_rate>100</update_rate>
        <imu>
          <angular_velocity>
            <x>
              <noise type="gaussian">
                <mean>0.0</mean>
                <stddev>2e-4</stddev>
              </noise>
            </x>
            <y>
              <noise type="gaussian">
                <mean>0.0</mean>
                <stddev>2e-4</stddev>
              </noise>
            </y>
            <z>
              <noise type="gaussian">
                <mean>0.0</mean>
                <stddev>2e-4</stddev>
              </noise>
            </z>
          </angular_velocity>
          <linear_acceleration>
            <x>
              <noise type="gaussian">
                <mean>0.0</mean>
                <stddev>1.7e-2</stddev>
              </noise>
            </x>
            <y>
              <noise type="gaussian">
                <mean>0.0</mean>
                <stddev>1.7e-2</stddev>
              </noise>
            </y>
            <z>
              <noise type="gaussian">
                <mean>0.0</mean>
                <stddev>1.7e-2</stddev>
              </noise>
            </z>
          </linear_acceleration>
        </imu>
        <plugin name="bytes_imu" filename="libgazebo_ros_imu_sensor.so">
            <ros>
                <namespace>imu</namespace>
                <remapping>~/out:=data</remapping>
            </ros>
            <initial_orientation_as_reference>false</initial_orientation_as_reference>
        </plugin>
    </sensor>
  </gazebo>
  <!--GPS-->
  <gazebo>
    <plugin filename="libhector_gazebo_ros_gps.so" name="gps_controller">
      <alwayson>true</alwayson>
      <updaterate>50</updaterate>
      <bodyname>gps</bodyname>
      <topicname>/fix</topicname>
      <frameId>robot_footprint</frameId>
      <velocitytopicname>/fix_velocity</velocitytopicname>
      <referenceLatitude>0</referenceLatitude>
      <referenceLongitude>0</referenceLongitude>
      <referenceHeading>90</referenceHeading>
      <referenceAltitude>1</referenceAltitude>
      <offset>0 0 0</offset>
      <drift>0 0 0</drift>
      <gaussianNoise>0 0 0</gaussianNoise>
      <velocityDrift>0 0 0</velocityDrift>
      <velocityGaussianNoise>0 0 0 </velocityGaussianNoise>
    </plugin>
  </gazebo>
  <!-- ZED2 Camera Plugin -->
  <gazebo reference="zed2_camera">
    <sensor name="zed2_camera_camera" type="depth">
      <update_rate>20</update_rate>
      <camera>
        <horizontal_fov>1.9</horizontal_fov>
        <image>
          <width>640</width>
          <height>480</height>
          <format>R8G8B8</format>
        </image>
        <clip>
          <near>0.0001</near>
          <far>3</far>
        </clip>
      </camera>
      <plugin filename="libgazebo_ros_camera.so" name="zed2_camera_controller">
        <baseline>0.2</baseline>
        <alwaysOn>true</alwaysOn>
        <updateRate>1.0</updateRate>
        <cameraName>zed2_ir</cameraName>
        <imageTopicName>/zed2/color/image_raw</imageTopicName>
        <cameraInfoTopicName>/zed2/color/camera_info</cameraInfoTopicName>
        <depthImageTopicName>/zed2/depth/image_raw</depthImageTopicName>
        <depthImageInfoTopicName>/zed2/depth/camera_info</depthImageInfoTopicName>
        <pointCloudTopicName>/zed2/depth/points</pointCloudTopicName>
        <frameName>zed2_optical</frameName>
        <pointCloudCutoff>0.0001</pointCloudCutoff>
        <pointCloudCutoffMax>3.0</pointCloudCutoffMax>
        <distortionK1>0.00000001</distortionK1>
        <distortionK2>0.00000001</distortionK2>
        <distortionK3>0.00000001</distortionK3>
        <distortionT1>0.00000001</distortionT1>
        <distortionT2>0.00000001</distortionT2>
        <CxPrime>0</CxPrime>
        <Cx>0</Cx>
        <Cy>0</Cy>
        <focalLength>0</focalLength>
        <hackBaseline>0</hackBaseline>
      </plugin>
    </sensor>
  </gazebo>
  <!-- Materials-->
  <material name="white">
    <color rgba="1 1 1 1"/>
  </material>
  <material name="orange">
    <color rgba="1 0.3 0.1 1"/>
  </material>
  <material name="blue">
    <color rgba="0.2 0.2 1 1"/>
  </material>
  <material name="black">
    <color rgba="0 0 0 1"/>
  </material>
  <material name="red">
    <color rgba="1 0 0 1"/>
  </material>
  <!-- Chassis -->
  <link name="chassis">
    <pose>0 0 0.1 0 0 0</pose>
    <inertial>
      <mass value="7"/>
      <origin rpy=" 0 0 0" xyz="0.0 0 0"/>
      <inertia ixx="0.147116667" ixy="0" ixz="0" iyy="0.334951167" iyz="0" izz="0.3978345"/>
    </inertial>
    <collision name="collision">
      <origin rpy=" 0 0 0" xyz="0 0 0.05"/>
      <geometry>
        <box size="0.55 0.5 0.2"/>
      </geometry>
    </collision>
    <visual name="chassis_visual">
      <origin rpy=" 0 0 0" xyz="0 0 0.05"/>
      <geometry>
        <box size="0.55 0.5 0.2"/>
      </geometry>
      <material name="blue"/>
    </visual>
  </link>
  <!-- Right Wheel Back -->
  <link name="right_wheel_back">
    <inertial>
      <mass value="1"/>
      <origin rpy="0 1.5707 1.5707" xyz="0 0 0"/>
      <inertia ixx="0.1" ixy="0.0" ixz="0.0" iyy="0.1" iyz="0.0" izz="0.1"/>
    </inertial>
    <visual>
      <origin rpy="0 1.5707 1.5707" xyz="0 0 0"/>
      <geometry>
        <cylinder length="0.1" radius="0.1"/>
      </geometry>
      <material name="black"/>
    </visual>
    <collision>
      <origin rpy="0 1.5707 1.5707" xyz="0 0 0"/>
      <geometry>
        <cylinder length="0.1" radius="0.1"/>
      </geometry>
    </collision>
  </link>
  <!-- Right Wheel Front-->
  <link name="right_wheel_front">
    <inertial>
      <mass value="1"/>
      <origin rpy="0 1.5707 1.5707" xyz="0 0 0"/>
      <inertia ixx="0.1" ixy="0.0" ixz="0.0" iyy="0.1" iyz="0.0" izz="0.1"/>
    </inertial>
    <visual>
      <origin rpy="0 1.5707 1.5707" xyz="0 0 0"/>
      <geometry>
        <cylinder length="0.1" radius="0.1"/>
      </geometry>
      <material name="black"/>
    </visual>
    <collision>
      <origin rpy="0 1.5707 1.5707" xyz="0 0 0"/>
      <geometry>
        <cylinder length="0.1" radius="0.1"/>
      </geometry>
    </collision>
  </link>
  <!-- Left wheel Back-->
  <link name="left_wheel_back">
    <inertial>
      <mass value="1"/>
      <origin rpy="0 1.5707 1.5707" xyz="0 0 0"/>
      <inertia ixx="0.1" ixy="0.0" ixz="0.0" iyy="0.1" iyz="0.0" izz="0.1"/>
    </inertial>
    <visual>
      <origin rpy="0 1.5707 1.5707" xyz="0 0 0"/>
      <geometry>
        <cylinder length="0.1" radius="0.1"/>
      </geometry>
      <material name="black"/>
    </visual>
    <collision>
      <origin rpy="0 1.5707 1.5707" xyz="0 0 0"/>
      <geometry>
        <cylinder length="0.1" radius="0.1"/>
      </geometry>
    </collision>
  </link>
  <!-- Left wheel Front-->
  <link name="left_wheel_front">
    <inertial>
      <mass value="1"/>
      <origin rpy="0 1.5707 1.5707" xyz="0 0 0"/>
      <inertia ixx="0.1" ixy="0.0" ixz="0.0" iyy="0.1" iyz="0.0" izz="0.1"/>
    </inertial>
    <visual>
      <origin rpy="0 1.5707 1.5707" xyz="0 0 0"/>
      <geometry>
        <cylinder length="0.1" radius="0.1"/>
      </geometry>
      <material name="black"/>
    </visual>
    <collision>
      <origin rpy="0 1.5707 1.5707" xyz="0 0 0"/>
      <geometry>
        <cylinder length="0.1" radius="0.1"/>
      </geometry>
    </collision>
  </link>
  <!-- Camera -->
  <link name="camera">
    <inertial>
      <mass value="0.1"/>
      <origin rpy="0 0 0" xyz="0 0 0"/>
      <inertia ixx="1e-6" ixy="0.0" ixz="0.0" iyy="1e-6" iyz="0.0" izz="1e-6"/>
    </inertial>
    <visual>
      <origin rpy="0 0 0" xyz="0 0 0"/>
      <geometry>
        <box size="0.05 0.05 0.05"/>
      </geometry>
      <material name="black"/>
    </visual>
    <collision>
      <origin rpy="0 0 0" xyz="0 0 0"/>
      <geometry>
        <box size="0.05 0.05 0.05"/>
      </geometry>
    </collision>
  </link>
  <!-- lidar  -->
  <link name="lidar">
    <inertial>
      <mass value="1e-05"/>
      <origin rpy="0 0 0" xyz="0 0 0"/>
      <inertia ixx="1e-6" ixy="0.0" ixz="0.0" iyy="1e-6" iyz="0.0" izz="1e-6"/>
    </inertial>
    <visual>
      <origin rpy="0 0 0" xyz="0 0 0"/>
      <geometry>
        <cylinder length="0.08" radius="0.06"/>
      </geometry>
      <material name="black"/>
    </visual>
    <collision>
      <origin rpy="0 0 0" xyz="0 0 0"/>
      <geometry>
        <cylinder length="0.08" radius="0.06"/>
      </geometry>
    </collision>
  </link>
  <!--imu-->
  <link name="imu">
    <inertial>
      <mass value="1e-05"/>
      <origin rpy=" 0 0 0" xyz="0 0 0"/>
      <inertia ixx="1e-6" ixy="0.0" ixz="0.0" iyy="1e-6" iyz="0.0" izz="1e-6"/>
    </inertial>
    <collision>
      <origin rpy=" 0 0 0" xyz="0 0 0"/>
      <geometry>
        <box size="0.05 0.05 0.05"/>
      </geometry>
    </collision>
    <visual>
      <geometry>
        <box size="0.05 0.05 0.05"/>
      </geometry>
      <material name="white"/>
    </visual>
  </link>
  <!--gps-->
  <link name="gps">
    <inertial>
      <mass value="1e-05"/>
      <origin rpy=" 0 0 0" xyz="0 0 0"/>
      <inertia ixx="1e-6" ixy="0.0" ixz="0.0" iyy="1e-6" iyz="0.0" izz="1e-6"/>
    </inertial>
    <collision>
      <origin rpy=" 0 0 0" xyz="0 0 0"/>
      <geometry>
        <box size="0.05 0.05 0.05"/>
      </geometry>
    </collision>
    <visual>
      <geometry>
        <box size="0.05 0.05 0.05"/>
      </geometry>
      <material name="red"/>
    </visual>
  </link>
  <!--zed2-->
  <link name="zed2_camera">
    <inertial>
      <mass value="1e-05"/>
      <origin rpy="0 0 0" xyz="0 0 0"/>
      <inertia ixx="1e-6" ixy="0.0" ixz="0.0" iyy="1e-6" iyz="0.0" izz="1e-6"/>
    </inertial>
    <visual>
      <origin rpy="0 0 0" xyz="0 0 0"/>
      <geometry>
        <box size="0.05 0.05 0.05"/>
      </geometry>
      <material name="black"/>
    </visual>
    <collision>
      <origin rpy="0 0 0" xyz="0 0 0"/>
      <geometry>
        <box size="0.05 0.05 0.05"/>
      </geometry>
    </collision>
  </link>
  <!--  robot center  -->
  <link name="robot_footprint"/>
  <!--  Zed2 optical  -->
  <link name="zed2_optical"/>
  <!-- Joints -->
  <!-- Right Wheel Joint Back-->
  <joint name="right_wheel_hinge_back" type="continuous">
    <origin rpy="0 0 0" xyz="-0.2 -0.30 0"/>
    <parent link="chassis"/>
    <child link="right_wheel_back"/>
    <axis rpy="0 0 0" xyz="0 1 0"/>
    <limit effort="10000" velocity="1000"/>
    <dynamics damping="1.0" friction="1.0"/>
  </joint>
  <!-- Right Wheel Joint Front-->
  <joint name="right_wheel_hinge_front" type="continuous">
    <origin rpy="0 0 0" xyz="0.2 -0.30 0"/>
    <parent link="chassis"/>
    <child link="right_wheel_front"/>
    <axis rpy="0 0 0" xyz="0 1 0"/>
    <limit effort="10000" velocity="1000"/>
    <dynamics damping="1.0" friction="1.0"/>
  </joint>
  <!-- Left Wheel Joint Back-->
  <joint name="left_wheel_hinge_back" type="continuous">
    <origin rpy="0 0 0" xyz="-0.2 0.30 0"/>
    <parent link="chassis"/>
    <child link="left_wheel_back"/>
    <axis rpy="0 0 0" xyz="0 1 0"/>
    <limit effort="10000" velocity="1000"/>
    <dynamics damping="1.0" friction="1.0"/>
  </joint>
  <!-- Left Wheel Joint Front-->
  <joint name="left_wheel_hinge_front" type="continuous">
    <origin rpy="0 0 0" xyz="0.2 0.30 0"/>
    <parent link="chassis"/>
    <child link="left_wheel_front"/>
    <axis rpy="0 0 0" xyz="0 1 0"/>
    <limit effort="10000" velocity="1000"/>
    <dynamics damping="1.0" friction="1.0"/>
  </joint>
  <!-- Camera Joint -->
  <joint name="camera_joint" type="fixed">
    <origin rpy="0 0 0" xyz="0.28 0 0.1"/>
    <parent link="chassis"/>
    <child link="camera"/>
    <axis xyz="0 1 0"/>
  </joint>
  <!-- Zed2 Joint -->
  <joint name="zed2_joint" type="fixed">
    <origin rpy="0 0 0" xyz="0.28 0 0.0"/>
    <parent link="chassis"/>
    <child link="zed2_camera"/>
    <axis xyz="0 1 0"/>
  </joint>
  <!-- Zed2 Optical Joint -->
  <joint name="zed2_optical_joint" type="fixed">
    <origin rpy="-1.5707963267948966 0 -1.5707963267948966" xyz="0 0 0"/>
    <parent link="zed2_camera"/>
    <child link="zed2_optical"/>
  </joint>
  <!-- Lidar Joint -->
  <joint name="lidar_joint" type="fixed">
    <origin rpy="0 0 0" xyz="0.2 0 0.17"/>
    <parent link="chassis"/>
    <child link="lidar"/>
    <axis xyz="0 1 0"/>
  </joint>
  <joint name="robot_footprint_joint" type="fixed">
    <origin rpy="0 0 0" xyz="0 0 0"/>
    <parent link="robot_footprint"/>
    <child link="chassis"/>
  </joint>
  <!--IMU Joint -->
  <joint name="imu_joint" type="fixed">
    <parent link="chassis"/>
    <child link="imu"/>
    <origin xyz="0 0 0.17"/>
  </joint>
  <!--GPS Joint-->
  <joint name="gps_joint" type="fixed">
    <parent link="chassis"/>
    <child link="gps"/>
    <origin xyz="0 0 0.22"/>
  </joint>
  <!-- Color -->
  <gazebo reference="left_wheel_front">
    <material>Gazebo/Black</material>
    <kp>1000000.0</kp>
    <!-- kp and kd for rubber -->
    <kd>100.0</kd>
    <mu1>1.0</mu1>
    <mu2>1.0</mu2>
    <maxVel>1.0</maxVel>
    <minDepth>0.00</minDepth>
  </gazebo>
  <gazebo reference="left_wheel_back">
    <material>Gazebo/Black</material>
    <kp>1000000.0</kp>
    <!-- kp and kd for rubber -->
    <kd>100.0</kd>
    <mu1>1.0</mu1>
    <mu2>1.0</mu2>
    <maxVel>1.0</maxVel>
    <minDepth>0.00</minDepth>
  </gazebo>
  <gazebo reference="right_wheel_front">
    <material>Gazebo/Black</material>
    <kp>1000000.0</kp>
    <!-- kp and kd for rubber -->
    <kd>100.0</kd>
    <mu1>1.0</mu1>
    <mu2>1.0</mu2>
    <maxVel>1.0</maxVel>
    <minDepth>0.00</minDepth>
  </gazebo>
  <gazebo reference="right_wheel_back">
    <material>Gazebo/Black</material>
    <kp>1000000.0</kp>
    <!-- kp and kd for rubber -->
    <kd>100.0</kd>
    <mu1>1.0</mu1>
    <mu2>1.0</mu2>
    <maxVel>1.0</maxVel>
    <minDepth>0.00</minDepth>
  </gazebo>
  <gazebo reference="camera">
    <material>Gazebo/Black</material>
  </gazebo>
  <gazebo reference="zed2_camera">
    <material>Gazebo/Black</material>
  </gazebo>
  <gazebo reference="lidar">
    <material>Gazebo/Black</material>
  </gazebo>
  <gazebo reference="gps">
    <material>Gazebo/Red</material>
  </gazebo>
  <gazebo reference="imu">
    <material>Gazebo/White</material>
  </gazebo>
  <gazebo reference="chassis">
    <material>Gazebo/Blue</material>
  </gazebo>
</robot>
