<?xml version='1.0'?>

<robot name="rover" xmlns:xacro="http://www.ros.org/wiki/xacro">
	<xacro:property name="robot_name" value="rover" />
	<xacro:property name="robot_chassis_mass" value="7"/>
	<xacro:property name="robot_chassis_length" value="0.2"/>
	<xacro:property name="robot_chassis_radius" value="0.25"/>

	<xacro:property name="robot_wheel_mass" value="1"/>
	<xacro:property name="robot_wheel_length" value="0.1"/>
	<xacro:property name="robot_wheel_radius" value="0.1"/>

	<xacro:property name="camera_mass" value="0.1"/>
	<xacro:property name="lidar_mass" value="1e-5"/>
	<xacro:property name="imu_mass" value="1e-5"/>
	<xacro:property name="gps_mass" value="1e-5"/>
	<xacro:property name="zed2_camera_mass" value="1e-5"/>

	<xacro:include filename="/home/aditi/ERC/leo_rover/urdf/rover.gazebo" />

	<!-- Materials-->

	  <material name="white">
	      <color rgba = "1 1 1 1"/>
	  </material>
	   <material name="orange">
	      <color rgba = "1 0.3 0.1 1"/>
	  </material>
	   <material name="blue">
	      <color rgba = "0.2 0.2 1 1"/>
	  </material>
	
	  <material name="black">
	      <color rgba = "0 0 0 1"/>
	  </material>
	
	  <material name="red">
	      <color rgba = "1 0 0 1"/>
	  </material>


	<!-- Chassis -->
	<link name="chassis">
		<pose>0 0 0.1 0 0 0</pose>

		<inertial>
			<mass value="${robot_chassis_mass}"/>
      		<origin xyz="0.0 0 0" rpy=" 0 0 0"/>

      		<inertia 
      			ixx="0.147116667" ixy="0" ixz="0"
      			iyy="0.334951167" iyz="0"
      			izz="0.3978345"
      		/>
		</inertial>

		<collision name="collision">
			<origin xyz="0 0 0.05" rpy=" 0 0 0"/>
			<geometry>
				<box size="0.55 0.5 0.2"/>
			</geometry>
		</collision>

		<visual name="chassis_visual">
			<origin xyz="0 0 0.05" rpy=" 0 0 0"/>
			<geometry>
				<box size="0.55 0.5 0.2"/>
			</geometry>
			<material name="blue"/>
		</visual>

	</link>


	<!-- Right Wheel Back -->
	<link name="right_wheel_back">
		<inertial>
			<mass value="${robot_wheel_mass}"/>
			<origin xyz="0 0 0" rpy="0 1.5707 1.5707"/>
			<inertia
				ixx="0.1" ixy="0.0" ixz="0.0"
				iyy="0.1" iyz="0.0"
				izz="0.1"
			/>
		</inertial>

		<visual>
			<origin xyz="0 0 0" rpy="0 1.5707 1.5707"/>
			<geometry>
				<cylinder radius="${robot_wheel_radius}" length="${robot_wheel_length}"/>
			</geometry>
			<material name = "black"/>
		</visual>

		<collision>
			<origin xyz="0 0 0" rpy="0 1.5707 1.5707"/>
			<geometry>
				<cylinder radius="${robot_wheel_radius}" length="${robot_wheel_length}"/>
			</geometry>
		</collision>

	</link>

	<!-- Right Wheel Front-->
	<link name="right_wheel_front">
		<inertial>
			<mass value="${robot_wheel_mass}"/>
			<origin xyz="0 0 0" rpy="0 1.5707 1.5707"/>
			<inertia
				ixx="0.1" ixy="0.0" ixz="0.0"
				iyy="0.1" iyz="0.0"
				izz="0.1"
			/>
		</inertial>

		<visual>
			<origin xyz="0 0 0" rpy="0 1.5707 1.5707"/>
			<geometry>
				<cylinder radius="${robot_wheel_radius}" length="${robot_wheel_length}"/>
			</geometry>
			<material name = "black"/>
		</visual>

		<collision>
			<origin xyz="0 0 0" rpy="0 1.5707 1.5707"/>
			<geometry>
				<cylinder radius="${robot_wheel_radius}" length="${robot_wheel_length}"/>
			</geometry>
		</collision>

	</link>



	<!-- Left wheel Back-->
	<link name="left_wheel_back">
		<inertial>
			<mass value="${robot_wheel_mass}"/>
			<origin xyz="0 0 0" rpy="0 1.5707 1.5707"/>
			<inertia
				ixx="0.1" ixy="0.0" ixz="0.0"
				iyy="0.1" iyz="0.0"
				izz="0.1"
			/>
		</inertial>

		<visual>
			<origin xyz="0 0 0" rpy="0 1.5707 1.5707"/>
			<geometry>
				<cylinder radius="${robot_wheel_radius}" length="${robot_wheel_length}"/>
			</geometry>
			<material name = "black"/>
		</visual>

		<collision>
			<origin xyz="0 0 0" rpy="0 1.5707 1.5707"/>
			<geometry>
				<cylinder radius="${robot_wheel_radius}" length="${robot_wheel_length}"/>
			</geometry>
		</collision>

	</link>

	<!-- Left wheel Front-->
	<link name="left_wheel_front">
		<inertial>
			<mass value="${robot_wheel_mass}"/>
			<origin xyz="0 0 0" rpy="0 1.5707 1.5707"/>
			<inertia
				ixx="0.1" ixy="0.0" ixz="0.0"
				iyy="0.1" iyz="0.0"
				izz="0.1"
			/>
		</inertial>

		<visual>
			<origin xyz="0 0 0" rpy="0 1.5707 1.5707"/>
			<geometry>
				<cylinder radius="${robot_wheel_radius}" length="${robot_wheel_length}"/>
			</geometry>
			<material name = "black"/>
		</visual>

		<collision>
			<origin xyz="0 0 0" rpy="0 1.5707 1.5707"/>
			<geometry>
				<cylinder radius="${robot_wheel_radius}" length="${robot_wheel_length}"/>
			</geometry>
		</collision>

	</link>

	<!-- Camera -->
	<link name="camera">
		<inertial>
			<mass value="${camera_mass}"/>
			<origin xyz="0 0 0" rpy="0 0 0"/>
			<inertia
		        ixx="1e-6" ixy="0.0" ixz="0.0"
		        iyy="1e-6" iyz="0.0"
		        izz="1e-6"
		      />
		</inertial>

		<visual>
			<origin xyz="0 0 0" rpy="0 0 0"/>
			<geometry>
				<box size="0.05 0.05 0.05"/>
			</geometry>
			<material name = "black"/>
		</visual>

		<collision>
			<origin xyz="0 0 0" rpy="0 0 0"/>
			<geometry>
				<box size="0.05 0.05 0.05"/>
			</geometry>
		</collision>
	</link>

	<!-- lidar  -->
	<link name="lidar">
		<inertial>
			<mass value="${lidar_mass}"/>
			<origin xyz="0 0 0" rpy="0 0 0"/>

			<inertia
		        ixx="1e-6" ixy="0.0" ixz="0.0"
		        iyy="1e-6" iyz="0.0"
		        izz="1e-6"
		      />
		</inertial>

		<visual>
			<origin xyz="0 0 0" rpy="0 0 0"/>
			<geometry>
				<cylinder radius="0.06" length="0.08"/>
			</geometry>
			<material name="black"/>
		</visual>

		<collision>
			<origin xyz="0 0 0" rpy="0 0 0"/>
			<geometry>
				<cylinder radius="0.06" length="0.08"/>
			</geometry>
		</collision>
	</link>

	<!--imu-->
  <link name="imu">
    <inertial>
      <mass value="${imu_mass}"/>
      <origin xyz="0 0 0" rpy=" 0 0 0"/>

			<inertia
		        ixx="1e-6" ixy="0.0" ixz="0.0"
		        iyy="1e-6" iyz="0.0"
		        izz="1e-6"
		      />
    </inertial>

    <collision>
    <origin xyz="0 0 0" rpy=" 0 0 0"/>
      <geometry>
        <box size="0.05 0.05 0.05"/>
      </geometry>  
    </collision>

    <visual>
      <geometry>
        <box size="0.05 0.05 0.05"/>
      </geometry>
	  <material name="white"/>
    </visual>

  </link>

	<!--gps-->
  <link name="gps">
    <inertial>
      <mass value="${gps_mass}"/>
      <origin xyz="0 0 0" rpy=" 0 0 0"/>

		<inertia
		    ixx="1e-6" ixy="0.0" ixz="0.0"
		    iyy="1e-6" iyz="0.0"
		    izz="1e-6"
		  />
    </inertial>

    <collision>
    <origin xyz="0 0 0" rpy=" 0 0 0"/>
      <geometry>
        <box size="0.05 0.05 0.05"/>
      </geometry>  
    </collision>

    <visual>
      <geometry>
        <box size="0.05 0.05 0.05"/>
      </geometry>
	  <material name="red"/>
    </visual>

  </link>

  	<!--zed2-->

	<link name="zed2_camera">
		<inertial>
			<mass value="${zed2_camera_mass}"/>
			<origin xyz="0 0 0" rpy="0 0 0"/>
			<inertia
		        ixx="1e-6" ixy="0.0" ixz="0.0"
		        iyy="1e-6" iyz="0.0"
		        izz="1e-6"
		      />
		</inertial>

		<visual>
			<origin xyz="0 0 0" rpy="0 0 0"/>
			<geometry>
				<box size="0.05 0.05 0.05"/>
			</geometry>
			<material name = "black"/>
		</visual>

		<collision>
			<origin xyz="0 0 0" rpy="0 0 0"/>
			<geometry>
				<box size="0.05 0.05 0.05"/>
			</geometry>
		</collision>
	</link>



	<!--  robot center  -->
	<link name="robot_footprint"></link>

	<!--  Zed2 optical  -->
	<link name="zed2_optical"></link>

	<!-- Joints -->

	<!-- Right Wheel Joint Back-->
	<joint type="continuous" name="right_wheel_hinge_back">
	    <origin xyz="-0.2 -0.30 0" rpy="0 0 0" />
	    <parent link="chassis"/>
	    <child link="right_wheel_back" />
	    <axis xyz="0 1 0" rpy="0 0 0" />
	    <limit effort="10000" velocity="1000" />
	    <dynamics damping="1.0" friction="1.0" />
	</joint>

	<!-- Right Wheel Joint Front-->
	<joint type="continuous" name="right_wheel_hinge_front">
	    <origin xyz="0.2 -0.30 0" rpy="0 0 0" />
	    <parent link="chassis"/>
	    <child link="right_wheel_front" />
	    <axis xyz="0 1 0" rpy="0 0 0" />
	    <limit effort="10000" velocity="1000" />
	    <dynamics damping="1.0" friction="1.0" />
	</joint>


	<!-- Left Wheel Joint Back-->
	<joint type="continuous" name="left_wheel_hinge_back">
	    <origin xyz="-0.2 0.30 0" rpy="0 0 0" />
	    <parent link="chassis"/>
	    <child link="left_wheel_back" />
	    <axis xyz="0 1 0" rpy="0 0 0" />
	    <limit effort="10000" velocity="1000" />
	    <dynamics damping="1.0" friction="1.0" />
	</joint>

	<!-- Left Wheel Joint Front-->
	<joint type="continuous" name="left_wheel_hinge_front">
	    <origin xyz="0.2 0.30 0" rpy="0 0 0" />
	    <parent link="chassis"/>
	    <child link="left_wheel_front" />
	    <axis xyz="0 1 0" rpy="0 0 0" />
	    <limit effort="10000" velocity="1000" />
	    <dynamics damping="1.0" friction="1.0" />
	</joint>

	<!-- Camera Joint -->
	<joint name="camera_joint" type="fixed">
		<origin xyz="0.28 0 0.1" rpy="0 0 0" />
		<parent link="chassis"/>
		<child link="camera" />
		<axis xyz="0 1 0"/>
	</joint>

	<!-- Zed2 Joint -->
	<joint name="zed2_joint" type="fixed">
		<origin xyz="0.28 0 0.0" rpy="0 0 0" />
		<parent link="chassis"/>
		<child link="zed2_camera" />
		<axis xyz="0 1 0"/>
	</joint>
	<!-- Zed2 Optical Joint -->
  	<joint name="zed2_optical_joint" type="fixed">
  	  <origin xyz="0 0 0" rpy="${-pi/2} 0 ${-pi/2}"/>
  	  <parent link="zed2_camera"/>
  	  <child link="zed2_optical"/>
  	</joint>

	<!-- Lidar Joint -->
	<joint name="lidar_joint" type="fixed">
	    <origin xyz="0.2 0 0.17" rpy="0 0 0" />
	    <parent link="chassis"/>
	    <child link="lidar" />  
	    <axis xyz="0 1 0"/> 
	</joint>

	<joint name="robot_footprint_joint" type="fixed">
		<origin xyz="0 0 0" rpy="0 0 0" />
		<parent link="robot_footprint"/>
		<child link="chassis" />
	</joint>

	<!--IMU Joint -->
	<joint name="imu_joint" type="fixed">
    	<parent link="chassis"/>
    	<child link="imu"/>
    	<origin xyz="0 0 0.17"/>
  	</joint>
	<!--GPS Joint-->

  	<joint name="gps_joint" type="fixed">
    	<parent link="chassis"/>
    	<child link="gps"/>
    	<origin xyz="0 0 0.22"/>
  	</joint>

	<!-- Color -->
	<gazebo reference="left_wheel_front">
		<material>Gazebo/Black</material>
		<kp>1000000.0</kp> <!-- kp and kd for rubber -->
		<kd>100.0</kd>
		<mu1>1.0</mu1>
		<mu2>1.0</mu2>
		<maxVel>1.0</maxVel>
		<minDepth>0.00</minDepth>
	</gazebo>

	<gazebo reference="left_wheel_back">
		<material>Gazebo/Black</material>
		<kp>1000000.0</kp> <!-- kp and kd for rubber -->
		<kd>100.0</kd>
		<mu1>1.0</mu1>
		<mu2>1.0</mu2>
		<maxVel>1.0</maxVel>
		<minDepth>0.00</minDepth>
	</gazebo>

	<gazebo reference="right_wheel_front">
		<material>Gazebo/Black</material>
		<kp>1000000.0</kp> <!-- kp and kd for rubber -->
		<kd>100.0</kd>
		<mu1>1.0</mu1>
		<mu2>1.0</mu2>
		<maxVel>1.0</maxVel>
		<minDepth>0.00</minDepth>
	</gazebo>
	<gazebo reference="right_wheel_back">
		<material>Gazebo/Black</material>
		<kp>1000000.0</kp> <!-- kp and kd for rubber -->
		<kd>100.0</kd>
		<mu1>1.0</mu1>
		<mu2>1.0</mu2>
		<maxVel>1.0</maxVel>
		<minDepth>0.00</minDepth>
	</gazebo>

	<gazebo reference="camera">
		<material>Gazebo/Black</material>
	</gazebo>

	<gazebo reference="zed2_camera">
		<material>Gazebo/Black</material>
	</gazebo>

	<gazebo reference="lidar">
		<material>Gazebo/Black</material>
	</gazebo>

	<gazebo reference="gps">
		<material>Gazebo/Red</material>
	</gazebo>
	<gazebo reference="imu">
		<material>Gazebo/White</material>
	</gazebo>

	<gazebo reference="chassis">
		<material>Gazebo/Blue</material>
	</gazebo>



</robot>
